src\core\exceptions.py:342: error: Incompatible types in assignment (expression has type "int", target has type "str")  [assignment]
src\core\exceptions.py:366: error: Incompatible types in assignment (expression has type "tuple[Any, ...]", target has type "str")  [assignment]
src\core\exceptions.py:646: error: Incompatible types in assignment (expression has type "dict[str, Any]", target has type "Sequence[str]")  [assignment]
src\core\exceptions.py:732: error: Incompatible types in assignment (expression has type "int", target has type "str")  [assignment]
src\utils\metrics.py:771: error: "MLMetricsCollector" has no attribute "get_metrics"; maybe "_setup_metrics"?  [attr-defined]
src\utils\metrics.py:781: error: "MLMetricsCollector" has no attribute "get_metrics"; maybe "_setup_metrics"?  [attr-defined]
src\utils\metrics.py:800: error: "MLMetricsCollector" has no attribute "get_prometheus_metrics"  [attr-defined]
src\core\environment.py:572: error: Need type annotation for "template"  [var-annotated]
src\core\environment.py:580: error: Item "dict[str, Any]" of "list[Any] | dict[str, Any] | str" has no attribute "append"  [union-attr]
src\core\environment.py:580: error: Item "str" of "list[Any] | dict[str, Any] | str" has no attribute "append"  [union-attr]
src\core\environment.py:598: error: Name "_env_manager_instance" is not defined  [name-defined]
src\core\environment.py:599: error: Name "_env_manager_instance" is not defined  [name-defined]
src\utils\monitoring.py:69: note: By default the bodies of untyped functions are not checked, consider using --check-untyped-defs  [annotation-unchecked]
src\utils\monitoring.py:301: note: By default the bodies of untyped functions are not checked, consider using --check-untyped-defs  [annotation-unchecked]
src\utils\monitoring.py:630: error: Incompatible types in assignment (expression has type "float", variable has type "int")  [assignment]
src\utils\monitoring.py:645: error: Incompatible types in assignment (expression has type "float", variable has type "int")  [assignment]
src\integration\discovery_publisher.py:301: error: Incompatible types in assignment (expression has type "datetime", target has type "int")  [assignment]
src\integration\discovery_publisher.py:568: error: Incompatible types in assignment (expression has type "datetime", variable has type "None")  [assignment]
src\integration\discovery_publisher.py:1051: error: Unsupported target for indexed assignment ("Collection[str]")  [index]
src\integration\discovery_publisher.py:1058: error: Unsupported target for indexed assignment ("Collection[str]")  [index]
src\integration\discovery_publisher.py:1065: error: Unsupported target for indexed assignment ("Collection[str]")  [index]
src\integration\discovery_publisher.py:1103: error: Incompatible types in assignment (expression has type "Literal[False]", target has type "Collection[str]")  [assignment]
src\data\storage\database.py:103: error: Unexpected keyword argument "severity" for "DatabaseConnectionError"  [call-arg]
src\core\exceptions.py:242: note: "DatabaseConnectionError" defined here
src\data\storage\database.py:137: error: Argument 1 to "create_async_engine" has incompatible type "**dict[str, object]"; expected "str | URL"  [arg-type]
src\data\storage\database.py:265: error: Unexpected keyword argument "severity" for "DatabaseConnectionError"  [call-arg]
src\data\storage\database.py:293: error: Unexpected keyword argument "severity" for "DatabaseQueryError"  [call-arg]
src\core\exceptions.py:263: note: "DatabaseQueryError" defined here
src\data\storage\database.py:348: error: Unexpected keyword argument "error_type" for "DatabaseQueryError"  [call-arg]
src\data\storage\database.py:348: error: Unexpected keyword argument "severity" for "DatabaseQueryError"  [call-arg]
src\data\storage\database.py:359: error: Unexpected keyword argument "error_type" for "DatabaseQueryError"  [call-arg]
src\data\storage\database.py:359: error: Unexpected keyword argument "severity" for "DatabaseQueryError"  [call-arg]
src\data\storage\database.py:368: error: Unexpected keyword argument "severity" for "DatabaseQueryError"  [call-arg]
src\data\storage\database.py:418: error: Argument 2 to "execute" of "AsyncSession" has incompatible type "list[str]"; expected "Sequence[Mapping[str, Any]] | Mapping[str, Any] | None"  [arg-type]
src\data\storage\database.py:436: error: Unexpected keyword argument "severity" for "DatabaseQueryError"  [call-arg]
src\data\storage\database.py:490: error: Incompatible types in assignment (expression has type "float", target has type "Collection[str]")  [assignment]
src\data\storage\database.py:567: error: Argument 3 to "getattr" has incompatible type "int"; expected "Collection[str]"  [arg-type]
src\data\storage\database.py:568: error: Argument 3 to "getattr" has incompatible type "int"; expected "Collection[str]"  [arg-type]
src\data\storage\database.py:569: error: Argument 3 to "getattr" has incompatible type "int"; expected "Collection[str]"  [arg-type]
src\data\storage\database.py:570: error: Argument 3 to "getattr" has incompatible type "int"; expected "Collection[str]"  [arg-type]
src\data\storage\database.py:575: error: Unsupported left operand type for + ("Collection[str]")  [operator]
src\data\storage\database.py:576: error: Unsupported operand types for < ("int" and "Collection[str]")  [operator]
src\data\storage\database.py:581: error: Incompatible types in assignment (expression has type "int", target has type "Collection[str]")  [assignment]
src\data\storage\database.py:584: error: Unsupported operand types for > ("int" and "Collection[str]")  [operator]
src\data\storage\database.py:586: error: Unsupported operand types for > ("int" and "Collection[str]")  [operator]
src\data\storage\database.py:598: error: Unsupported operand types for < ("int" and "Collection[str]")  [operator]
src\data\storage\database.py:698: error: "Collection[str]" has no attribute "update"  [attr-defined]
src\data\storage\database.py:715: error: "Collection[str]" has no attribute "update"  [attr-defined]
src\data\storage\database.py:725: error: "Collection[str]" has no attribute "append"  [attr-defined]
src\data\storage\database.py:735: error: Incompatible types in assignment (expression has type "datetime", target has type "int")  [assignment]
src\data\storage\database.py:739: error: "Collection[str]" has no attribute "append"  [attr-defined]
src\models\base\lstm_predictor.py:46: error: "object" has no attribute "copy"  [attr-defined]
src\models\base\lstm_predictor.py:278: error: Missing positional argument "room_id" in call to "ModelPredictionError"  [call-arg]
src\models\base\lstm_predictor.py:281: error: Missing positional argument "room_id" in call to "ModelPredictionError"  [call-arg]
src\models\base\lstm_predictor.py:366: error: Missing positional argument "room_id" in call to "ModelPredictionError"  [call-arg]
src\models\base\hmm_predictor.py:45: error: "object" has no attribute "copy"  [attr-defined]
src\models\base\hmm_predictor.py:101: error: Missing positional argument "room_id" in call to "ModelTrainingError"  [call-arg]
src\models\base\hmm_predictor.py:246: error: Missing positional argument "room_id" in call to "ModelTrainingError"  [call-arg]
src\models\base\hmm_predictor.py:266: error: Missing positional argument "room_id" in call to "ModelPredictionError"  [call-arg]
src\models\base\hmm_predictor.py:269: error: Missing positional argument "room_id" in call to "ModelPredictionError"  [call-arg]
src\models\base\hmm_predictor.py:287: error: Argument 2 to "_predict_single_duration" of "HMMPredictor" has incompatible type "signedinteger[Any]"; expected "int"  [arg-type]
src\models\base\hmm_predictor.py:302: error: Argument 1 to "_determine_transition_type_from_states" of "HMMPredictor" has incompatible type "signedinteger[Any]"; expected "int"  [arg-type]
src\models\base\hmm_predictor.py:323: error: No overload variant of "get" of "dict" matches argument types "signedinteger[Any]", "str"  [call-overload]
src\models\base\hmm_predictor.py:323: note: Possible overload variants:
src\models\base\hmm_predictor.py:323: note:     def get(self, int, None = ..., /) -> str
src\models\base\hmm_predictor.py:323: note:     def get(self, int, str, /) -> str
src\models\base\hmm_predictor.py:323: note:     def [_T] get(self, int, _T, /) -> str | _T
src\models\base\hmm_predictor.py:345: error: Missing positional argument "room_id" in call to "ModelPredictionError"  [call-arg]
src\models\base\hmm_predictor.py:477: error: Dict entry 8 has incompatible type "str": "str"; expected "str": "float"  [dict-item]
src\models\base\hmm_predictor.py:587: error: Argument 2 to "_predict_single_duration" of "HMMPredictor" has incompatible type "signedinteger[Any]"; expected "int"  [arg-type]
src\models\base\gp_predictor.py:35: error: Name "PeriodicKernel" already defined (possibly by an import)  [no-redef]
src\models\base\gp_predictor.py:76: error: "object" has no attribute "copy"  [attr-defined]
src\models\base\gp_predictor.py:109: error: Need type annotation for "kernel_params_history" (hint: "kernel_params_history: list[<type>] = ...")  [var-annotated]
src\models\base\gp_predictor.py:439: error: Missing positional argument "room_id" in call to "ModelPredictionError"  [call-arg]
src\models\base\gp_predictor.py:442: error: Missing positional argument "room_id" in call to "ModelPredictionError"  [call-arg]
src\models\base\gp_predictor.py:531: error: Missing positional argument "room_id" in call to "ModelPredictionError"  [call-arg]
src\models\base\gp_predictor.py:610: error: Incompatible types in assignment (expression has type "ndarray[Any, Any]", variable has type "None")  [assignment]
src\models\base\gp_predictor.py:641: error: Incompatible types in assignment (expression has type "dict[float, Any]", variable has type "None")  [assignment]
src\models\base\gp_predictor.py:893: error: Missing positional argument "room_id" in call to "ModelTrainingError"  [call-arg]
src\models\base\gp_predictor.py:933: error: Incompatible types in assignment (expression has type "ndarray[Any, dtype[Any]]", variable has type "None")  [assignment]
src\models\base\gp_predictor.py:935: error: Incompatible types in assignment (expression has type "ndarray[Any, dtype[Any]]", variable has type "None")  [assignment]
src\models\base\gp_predictor.py:993: error: Dict entry 0 has incompatible type "str": "str"; expected "str": "float"  [dict-item]
src\models\base\gp_predictor.py:1029: error: Missing positional argument "room_id" in call to "ModelTrainingError"  [call-arg]
src\integration\mqtt_integration_manager.py:425: error: Unsupported operand types for > ("int" and "object")  [operator]
src\integration\mqtt_integration_manager.py:439: error: Unsupported operand types for < ("int" and "object")  [operator]
src\integration\mqtt_integration_manager.py:442: error: Unsupported operand types for < ("int" and "object")  [operator]
src\integration\mqtt_integration_manager.py:446: error: No overload variant of "max" matches argument types "int", "object"  [call-overload]
src\integration\mqtt_integration_manager.py:446: note: Possible overload variants:
src\integration\mqtt_integration_manager.py:446: note:     def [SupportsRichComparisonT: SupportsDunderLT[Any] | SupportsDunderGT[Any]] max(SupportsRichComparisonT, SupportsRichComparisonT, /, *_args: SupportsRichComparisonT, key: None = ...) -> SupportsRichComparisonT
src\integration\mqtt_integration_manager.py:446: note:     def [_T] max(_T, _T, /, *_args: _T, key: Callable[[_T], SupportsDunderLT[Any] | SupportsDunderGT[Any]]) -> _T
src\integration\mqtt_integration_manager.py:446: note:     def [SupportsRichComparisonT: SupportsDunderLT[Any] | SupportsDunderGT[Any]] max(Iterable[SupportsRichComparisonT], /, *, key: None = ...) -> SupportsRichComparisonT
src\integration\mqtt_integration_manager.py:446: note:     def [_T] max(Iterable[_T], /, *, key: Callable[[_T], SupportsDunderLT[Any] | SupportsDunderGT[Any]]) -> _T
src\integration\mqtt_integration_manager.py:446: note:     def [SupportsRichComparisonT: SupportsDunderLT[Any] | SupportsDunderGT[Any], _T] max(Iterable[SupportsRichComparisonT], /, *, key: None = ..., default: _T) -> SupportsRichComparisonT | _T
src\integration\mqtt_integration_manager.py:446: note:     def [_T1, _T2] max(Iterable[_T1], /, *, key: Callable[[_T1], SupportsDunderLT[Any] | SupportsDunderGT[Any]], default: _T2) -> _T1 | _T2
src\integration\mqtt_integration_manager.py:447: error: Unsupported operand types for / ("object" and "int")  [operator]
src\integration\ha_entity_definitions.py:90: error: Attempted to reuse member name "UPDATE" in Enum definition "HADeviceClass"  [misc]
src\integration\ha_entity_definitions.py:136: error: Attributes without a default cannot follow attributes with one  [misc]
src\integration\ha_entity_definitions.py:155: error: Attributes without a default cannot follow attributes with one  [misc]
src\integration\ha_entity_definitions.py:169: error: Attributes without a default cannot follow attributes with one  [misc]
src\integration\ha_entity_definitions.py:184: error: Attributes without a default cannot follow attributes with one  [misc]
src\integration\ha_entity_definitions.py:190: error: Attributes without a default cannot follow attributes with one  [misc]
src\integration\ha_entity_definitions.py:203: error: Attributes without a default cannot follow attributes with one  [misc]
src\integration\ha_entity_definitions.py:209: error: Attributes without a default cannot follow attributes with one  [misc]
src\integration\ha_entity_definitions.py:220: error: Attributes without a default cannot follow attributes with one  [misc]
src\integration\ha_entity_definitions.py:226: error: Attributes without a default cannot follow attributes with one  [misc]
src\integration\ha_entity_definitions.py:234: error: Attributes without a default cannot follow attributes with one  [misc]
src\integration\ha_entity_definitions.py:240: error: Attributes without a default cannot follow attributes with one  [misc]
src\integration\ha_entity_definitions.py:250: error: Attributes without a default cannot follow attributes with one  [misc]
src\integration\ha_entity_definitions.py:256: error: Attributes without a default cannot follow attributes with one  [misc]
src\integration\ha_entity_definitions.py:262: error: Attributes without a default cannot follow attributes with one  [misc]
src\integration\ha_entity_definitions.py:268: error: Attributes without a default cannot follow attributes with one  [misc]
src\integration\ha_entity_definitions.py:379: error: Incompatible types in assignment (expression has type "datetime", target has type "int")  [assignment]
src\integration\ha_entity_definitions.py:635: error: Incompatible types in assignment (expression has type "HABinarySensorEntityConfig", target has type "HASensorEntityConfig")  [assignment]
src\integration\ha_entity_definitions.py:662: error: Incompatible types in assignment (expression has type "HABinarySensorEntityConfig", target has type "HASensorEntityConfig")  [assignment]
src\integration\ha_entity_definitions.py:728: error: Incompatible return value type (got "dict[str, HASensorEntityConfig]", expected "dict[str, HAEntityConfig]")  [return-value]
src\integration\ha_entity_definitions.py:728: note: "dict" is invariant -- see https://mypy.readthedocs.io/en/stable/common_issues.html#variance
src\integration\ha_entity_definitions.py:728: note: Consider using "Mapping" instead, which is covariant in the value type
src\integration\ha_entity_definitions.py:728: note: Perhaps you need a type annotation for "entities"? Suggestion: "dict[str, HAEntityConfig]"
src\integration\ha_entity_definitions.py:805: error: Incompatible return value type (got "dict[str, HASensorEntityConfig]", expected "dict[str, HAEntityConfig]")  [return-value]
src\integration\ha_entity_definitions.py:805: note: "dict" is invariant -- see https://mypy.readthedocs.io/en/stable/common_issues.html#variance
src\integration\ha_entity_definitions.py:805: note: Consider using "Mapping" instead, which is covariant in the value type
src\integration\ha_entity_definitions.py:805: note: Perhaps you need a type annotation for "entities"? Suggestion: "dict[str, HAEntityConfig]"
src\integration\ha_entity_definitions.py:865: error: Incompatible types in assignment (expression has type "HASensorEntityConfig", target has type "HABinarySensorEntityConfig")  [assignment]
src\integration\ha_entity_definitions.py:880: error: Incompatible types in assignment (expression has type "HASensorEntityConfig", target has type "HABinarySensorEntityConfig")  [assignment]
src\integration\ha_entity_definitions.py:895: error: Incompatible types in assignment (expression has type "HASensorEntityConfig", target has type "HABinarySensorEntityConfig")  [assignment]
src\integration\ha_entity_definitions.py:936: error: Incompatible types in assignment (expression has type "HASensorEntityConfig", target has type "HABinarySensorEntityConfig")  [assignment]
src\integration\ha_entity_definitions.py:950: error: Incompatible types in assignment (expression has type "HASensorEntityConfig", target has type "HABinarySensorEntityConfig")  [assignment]
src\integration\ha_entity_definitions.py:962: error: Incompatible return value type (got "dict[str, HABinarySensorEntityConfig]", expected "dict[str, HAEntityConfig]")  [return-value]
src\integration\ha_entity_definitions.py:962: note: "dict" is invariant -- see https://mypy.readthedocs.io/en/stable/common_issues.html#variance
src\integration\ha_entity_definitions.py:962: note: Consider using "Mapping" instead, which is covariant in the value type
src\integration\ha_entity_definitions.py:962: note: Perhaps you need a type annotation for "entities"? Suggestion: "dict[str, HAEntityConfig]"
src\integration\ha_entity_definitions.py:1000: error: Incompatible types in assignment (expression has type "HANumberEntityConfig", target has type "HASwitchEntityConfig")  [assignment]
src\integration\ha_entity_definitions.py:1018: error: Incompatible types in assignment (expression has type "HASelectEntityConfig", target has type "HASwitchEntityConfig")  [assignment]
src\integration\ha_entity_definitions.py:1032: error: Incompatible types in assignment (expression has type "HANumberEntityConfig", target has type "HASwitchEntityConfig")  [assignment]
src\integration\ha_entity_definitions.py:1050: error: Incompatible types in assignment (expression has type "HANumberEntityConfig", target has type "HASwitchEntityConfig")  [assignment]
src\integration\ha_entity_definitions.py:1068: error: Incompatible types in assignment (expression has type "HASelectEntityConfig", target has type "HASwitchEntityConfig")  [assignment]
src\integration\ha_entity_definitions.py:1112: error: Incompatible types in assignment (expression has type "HATextEntityConfig", target has type "HASwitchEntityConfig")  [assignment]
src\integration\ha_entity_definitions.py:1126: error: Incompatible return value type (got "dict[str, HASwitchEntityConfig]", expected "dict[str, HAEntityConfig]")  [return-value]
src\integration\ha_entity_definitions.py:1126: note: "dict" is invariant -- see https://mypy.readthedocs.io/en/stable/common_issues.html#variance
src\integration\ha_entity_definitions.py:1126: note: Consider using "Mapping" instead, which is covariant in the value type
src\integration\ha_entity_definitions.py:1126: note: Perhaps you need a type annotation for "entities"? Suggestion: "dict[str, HAEntityConfig]"
src\integration\ha_entity_definitions.py:1476: error: Incompatible types in assignment (expression has type "Literal[False]", target has type "Collection[str]")  [assignment]
src\integration\ha_entity_definitions.py:1484: error: Incompatible types in assignment (expression has type "int", target has type "Collection[str]")  [assignment]
src\adaptation\optimizer.py:536: error: Missing positional argument "model_type" in call to "BasePredictor"  [call-arg]
src\adaptation\optimizer.py:537: error: "BasePredictor" has no attribute "set_parameters"  [attr-defined]
src\utils\alerts.py:92: note: By default the bodies of untyped functions are not checked, consider using --check-untyped-defs  [annotation-unchecked]
src\utils\alerts.py:93: note: By default the bodies of untyped functions are not checked, consider using --check-untyped-defs  [annotation-unchecked]
src\utils\alerts.py:319: note: By default the bodies of untyped functions are not checked, consider using --check-untyped-defs  [annotation-unchecked]
src\utils\alerts.py:320: note: By default the bodies of untyped functions are not checked, consider using --check-untyped-defs  [annotation-unchecked]
src\utils\alerts.py:581: error: "object" has no attribute "send_alert"  [attr-defined]
src\integration\websocket_api.py:38: error: Incompatible import of "validator" (imported name has type overloaded function, local name has type "Callable[[str, VarArg(str), DefaultNamedArg(bool, 'pre'), DefaultNamedArg(bool, 'each_item'), DefaultNamedArg(bool, 'always'), DefaultNamedArg(bool | None, 'check_fields'), DefaultNamedArg(bool, 'allow_reuse')], Callable[[_V1ValidatorType], _V1ValidatorType]]")  [assignment]
src\integration\websocket_api.py:302: error: Need type annotation for "_manager_registry"  [var-annotated]
src\integration\websocket_api.py:664: error: Incompatible types in assignment (expression has type "WebSocketServer", variable has type "None")  [assignment]
src\integration\websocket_api.py:868: error: Argument 2 to "_process_client_message" of "WebSocketAPIServer" has incompatible type "str | bytes"; expected "str"  [arg-type]
src\integration\websocket_api.py:1069: error: Item "dict[Never, Never]" of "ClientConnection | dict[Never, Never]" has no attribute "endpoint"  [union-attr]
src\integration\websocket_api.py:1097: error: Item "RoomConfig" of "RoomConfig | dict[Never, Never]" has no attribute "get"  [union-attr]
src\integration\websocket_api.py:1097: error: No overload variant of "get" of "dict" matches argument types "str", "str"  [call-overload]
src\integration\websocket_api.py:1097: note: Possible overload variants:
src\integration\websocket_api.py:1097: note:     def get(self, Never, None = ..., /) -> None
src\integration\websocket_api.py:1097: note:     def get(self, Never, Never, /) -> Never
src\integration\websocket_api.py:1097: note:     def [_T] get(self, Never, _T, /) -> _T
src\integration\realtime_publisher.py:124: note: By default the bodies of untyped functions are not checked, consider using --check-untyped-defs  [annotation-unchecked]
src\integration\realtime_publisher.py:125: note: By default the bodies of untyped functions are not checked, consider using --check-untyped-defs  [annotation-unchecked]
src\integration\realtime_publisher.py:258: note: By default the bodies of untyped functions are not checked, consider using --check-untyped-defs  [annotation-unchecked]
src\integration\realtime_publisher.py:259: note: By default the bodies of untyped functions are not checked, consider using --check-untyped-defs  [annotation-unchecked]
src\integration\realtime_publisher.py:267: error: Need type annotation for "queue"  [var-annotated]
src\integration\realtime_publisher.py:389: note: "RealtimePublishingSystem" defined here
src\integration\realtime_publisher.py:602: error: Incompatible types in assignment (expression has type "str", target has type "dict[str, object]")  [assignment]
src\integration\realtime_publisher.py:639: error: Dict entry 1 has incompatible type "str": "str"; expected "str": "int"  [dict-item]
src\integration\realtime_publisher.py:651: error: Dict entry 1 has incompatible type "str": "str"; expected "str": "int"  [dict-item]
src\integration\realtime_publisher.py:657: error: Incompatible types in assignment (expression has type "str", target has type "dict[str, int]")  [assignment]
src\integration\realtime_publisher.py:802: error: Item "RoomConfig" of "RoomConfig | dict[Never, Never]" has no attribute "get"  [union-attr]
src\integration\realtime_publisher.py:802: error: No overload variant of "get" of "dict" matches argument types "str", "str"  [call-overload]
src\integration\realtime_publisher.py:802: note: Possible overload variants:
src\integration\realtime_publisher.py:802: note:     def get(self, Never, None = ..., /) -> None
src\integration\realtime_publisher.py:802: note:     def get(self, Never, Never, /) -> Never
src\integration\realtime_publisher.py:802: note:     def [_T] get(self, Never, _T, /) -> _T
src\integration\realtime_publisher.py:1013: error: Argument 1 to "asynccontextmanager" has incompatible type "Callable[[dict[str, Any] | None, Any], RealtimePublishingSystem]"; expected "Callable[[dict[str, Any], Any], AsyncIterator[Never]]"  [arg-type]
src\integration\realtime_publisher.py:1014: error: The return type of an async generator function should be "AsyncGenerator" or one of its supertypes  [misc]
src\integration\realtime_publisher.py:1019: error: Unexpected keyword argument "config" for "RealtimePublishingSystem"  [call-arg]
src\integration\realtime_publisher.py:1019: error: Unexpected keyword argument "tracking_manager" for "RealtimePublishingSystem"  [call-arg]
src\integration\realtime_publisher.py:1024: error: "RealtimePublishingSystem" has no attribute "start"  [attr-defined]
src\integration\realtime_publisher.py:1027: error: "RealtimePublishingSystem" has no attribute "stop"  [attr-defined]
src\integration\realtime_publisher.py:1110: error: Unexpected keyword argument "config" for "RealtimePublishingSystem"  [call-arg]
src\integration\realtime_publisher.py:1110: error: Unexpected keyword argument "tracking_manager" for "RealtimePublishingSystem"  [call-arg]
src\integration\enhanced_integration_manager.py:113: error: Need type annotation for "command_queue"  [var-annotated]
src\integration\enhanced_integration_manager.py:343: error: "PredictionResult" has no attribute "time_until_human"  [attr-defined]
src\integration\enhanced_integration_manager.py:344: error: "PredictionResult" has no attribute "prediction_reliability"  [attr-defined]
src\integration\enhanced_integration_manager.py:356: error: "PredictionResult" has no attribute "time_until_human"  [attr-defined]
src\integration\enhanced_integration_manager.py:368: error: "PredictionResult" has no attribute "prediction_reliability"  [attr-defined]
src\integration\enhanced_integration_manager.py:784: error: Unsupported target for indexed assignment ("object")  [index]
src\utils\health_monitor.py:205: error: Need type annotation for "performance_metrics"  [var-annotated]
src\utils\health_monitor.py:381: error: "MLMetricsCollector" has no attribute "record_duration"  [attr-defined]
src\utils\health_monitor.py:384: error: "MLMetricsCollector" has no attribute "set_gauge"  [attr-defined]
src\utils\health_monitor.py:465: error: "MLMetricsCollector" has no attribute "increment"  [attr-defined]
src\utils\health_monitor.py:1146: error: Unexpected keyword argument "severity" for "trigger_alert" of "AlertManager"  [call-arg]
src\utils\alerts.py:486: note: "trigger_alert" of "AlertManager" defined here
src\utils\health_monitor.py:1192: error: "MLMetricsCollector" has no attribute "set_gauge"  [attr-defined]
src\utils\health_monitor.py:1195: error: "MLMetricsCollector" has no attribute "set_gauge"  [attr-defined]
src\utils\health_monitor.py:1198: error: "MLMetricsCollector" has no attribute "set_gauge"  [attr-defined]
src\utils\health_monitor.py:1201: error: "MLMetricsCollector" has no attribute "set_gauge"  [attr-defined]
src\utils\health_monitor.py:1204: error: "MLMetricsCollector" has no attribute "set_gauge"  [attr-defined]
src\utils\health_monitor.py:1219: error: "MLMetricsCollector" has no attribute "set_gauge_with_labels"  [attr-defined]
src\utils\health_monitor.py:1222: error: "MLMetricsCollector" has no attribute "set_gauge_with_labels"  [attr-defined]
src\utils\health_monitor.py:1225: error: "MLMetricsCollector" has no attribute "set_gauge_with_labels"  [attr-defined]
src\utils\health_monitor.py:1233: error: "MLMetricsCollector" has no attribute "set_gauge_with_labels"  [attr-defined]
src\integration\enhanced_mqtt_manager.py:176: error: "MQTTIntegrationManager" has no attribute "shutdown"  [attr-defined]
src\utils\incident_response.py:493: error: Unexpected keyword argument "severity" for "trigger_alert" of "AlertManager"  [call-arg]
src\utils\alerts.py:486: note: "trigger_alert" of "AlertManager" defined here
src\data\storage\models.py:61: error: Variable "src.data.storage.models.Base" is not valid as a type  [valid-type]
src\data\storage\models.py:61: note: See https://mypy.readthedocs.io/en/stable/common_issues.html#variables-vs-type-aliases
src\data\storage\models.py:61: error: Invalid base class "Base"  [misc]
src\data\storage\models.py:87: error: Need type annotation for "sensor_type"  [var-annotated]
src\data\storage\models.py:88: error: Need type annotation for "state"  [var-annotated]
src\data\storage\models.py:89: error: Need type annotation for "previous_state"  [var-annotated]
src\data\storage\models.py:162: error: Incompatible return value type (got "Sequence[SensorEvent]", expected "list[SensorEvent]")  [return-value]
src\data\storage\models.py:190: error: Incompatible return value type (got "Sequence[SensorEvent]", expected "list[SensorEvent]")  [return-value]
src\data\storage\models.py:209: error: Need type annotation for "current_sequence" (hint: "current_sequence: list[<type>] = ...")  [var-annotated]
src\data\storage\models.py:233: error: Incompatible return value type (got "Sequence[Prediction]", expected "list[Prediction]")  [return-value]
src\data\storage\models.py:500: error: Variable "src.data.storage.models.Base" is not valid as a type  [valid-type]
src\data\storage\models.py:500: note: See https://mypy.readthedocs.io/en/stable/common_issues.html#variables-vs-type-aliases
src\data\storage\models.py:500: error: Invalid base class "Base"  [misc]
src\data\storage\models.py:579: error: Incompatible return value type (got "Sequence[RoomState]", expected "list[RoomState]")  [return-value]
src\data\storage\models.py:585: error: Incompatible return value type (got "Sequence[Prediction]", expected "list[Prediction]")  [return-value]
src\data\storage\models.py:647: error: "object" has no attribute "append"  [attr-defined]
src\data\storage\models.py:673: error: Unsupported target for indexed assignment ("object")  [index]
src\data\storage\models.py:674: error: Value of type "object" is not indexable  [index]
src\data\storage\models.py:676: error: Unsupported target for indexed assignment ("object")  [index]
src\data\storage\models.py:677: error: Value of type "object" is not indexable  [index]
src\data\storage\models.py:685: error: Unsupported left operand type for - ("object")  [operator]
src\data\storage\models.py:690: error: "object" has no attribute "__iter__"; maybe "__dir__" or "__str__"? (not iterable)  [attr-defined]
src\data\storage\models.py:691: error: Argument 1 to "len" has incompatible type "object"; expected "Sized"  [arg-type]
src\data\storage\models.py:693: error: Unsupported target for indexed assignment ("object")  [index]
src\data\storage\models.py:762: error: Variable "src.data.storage.models.Base" is not valid as a type  [valid-type]
src\data\storage\models.py:762: note: See https://mypy.readthedocs.io/en/stable/common_issues.html#variables-vs-type-aliases
src\data\storage\models.py:762: error: Invalid base class "Base"  [misc]
src\data\storage\models.py:776: error: Need type annotation for "transition_type"  [var-annotated]
src\data\storage\models.py:784: error: Need type annotation for "model_type"  [var-annotated]
src\data\storage\models.py:858: error: Incompatible return value type (got "Sequence[Prediction]", expected "list[Prediction]")  [return-value]
src\data\storage\models.py:900: error: Dict entry 4 has incompatible type "str": "Column[float] | int"; expected "str": "float"  [dict-item]
src\data\storage\models.py:901: error: Value of type variable "SupportsRichComparisonT" of "sorted" cannot be "Column[float]"  [type-var]
src\data\storage\models.py:904: error: Unsupported operand types for ** ("Column[float]" and "int")  [operator]
src\data\storage\models.py:999: error: Need type annotation for "feature_data"  [var-annotated]
src\data\storage\models.py:1000: error: Need type annotation for "alternatives_data"  [var-annotated]
src\data\storage\models.py:1016: error: Argument 1 to "_extract_top_features" of "Prediction" has incompatible type "Column[Any] | dict[Any, Any]"; expected "dict[str, Any]"  [arg-type]
src\data\storage\models.py:1017: error: Argument 1 to "_categorize_features" of "Prediction" has incompatible type "Column[Any] | dict[Any, Any]"; expected "dict[str, Any]"  [arg-type]
src\data\storage\models.py:1026: error: Argument 1 to "_analyze_confidence_spread" of "Prediction" has incompatible type "Column[Any] | list[Any]"; expected "list[dict[str, Any]]"  [arg-type]
src\data\storage\models.py:1121: error: Need type annotation for "current_features"  [var-annotated]
src\data\storage\models.py:1134: error: Incompatible types in assignment (expression has type "dict[Any, Any]", variable has type "Column[Any]")  [assignment]
src\data\storage\models.py:1137: error: Variable "src.data.storage.models.Base" is not valid as a type  [valid-type]
src\data\storage\models.py:1137: note: See https://mypy.readthedocs.io/en/stable/common_issues.html#variables-vs-type-aliases
src\data\storage\models.py:1137: error: Invalid base class "Base"  [misc]
src\data\storage\models.py:1147: error: Need type annotation for "model_type"  [var-annotated]
src\data\storage\models.py:1200: error: Variable "src.data.storage.models.Base" is not valid as a type  [valid-type]
src\data\storage\models.py:1200: note: See https://mypy.readthedocs.io/en/stable/common_issues.html#variables-vs-type-aliases
src\data\storage\models.py:1200: error: Invalid base class "Base"  [misc]
src\data\storage\models.py:1278: error: Need type annotation for "features" (hint: "features: dict[<type>, <type>] = ...")  [var-annotated]
src\data\storage\models.py:1286: error: Variable "src.data.storage.models.Base" is not valid as a type  [valid-type]
src\data\storage\models.py:1286: note: See https://mypy.readthedocs.io/en/stable/common_issues.html#variables-vs-type-aliases
src\data\storage\models.py:1286: error: Invalid base class "Base"  [misc]
src\data\storage\models.py:1395: error: Incompatible return value type (got "Sequence[PredictionAudit]", expected "list[PredictionAudit]")  [return-value]
src\data\storage\models.py:1404: error: Need type annotation for "details"  [var-annotated]
src\data\storage\models.py:1417: error: Unsupported target for indexed assignment ("object")  [index]
src\data\storage\models.py:1418: error: "object" has no attribute "get"  [attr-defined]
src\data\storage\models.py:1447: error: Need type annotation for "current_metrics"  [var-annotated]
src\data\storage\models.py:1450: error: Incompatible types in assignment (expression has type "Column[Any] | dict[Any, Any]", variable has type "Column[Any]")  [assignment]
src\features\temporal.py:44: error: Need type annotation for "feature_cache" (hint: "feature_cache: dict[<type>, <type>] = ...")  [var-annotated]
src\features\temporal.py:71: error: Argument "key" to "sorted" has incompatible type "Callable[[SensorEvent], Column[datetime]]"; expected "Callable[[SensorEvent], SupportsDunderLT[Any] | SupportsDunderGT[Any]]"  [arg-type]
src\features\temporal.py:71: error: Incompatible return value type (got "Column[datetime]", expected "SupportsDunderLT[Any] | SupportsDunderGT[Any]")  [return-value]
src\features\temporal.py:104: error: Missing positional argument "room_id" in call to "FeatureExtractionError"  [call-arg]
src\features\temporal.py:256: error: Need type annotation for "features" (hint: "features: dict[<type>, <type>] = ...")  [var-annotated]
src\features\temporal.py:418: error: "None" not callable  [misc]
src\features\temporal.py:569: error: Argument "key" to "sorted" has incompatible type "Callable[[RoomState], Column[datetime]]"; expected "Callable[[RoomState], SupportsDunderLT[Any] | SupportsDunderGT[Any]]"  [arg-type]
src\features\temporal.py:569: error: Incompatible return value type (got "Column[datetime]", expected "SupportsDunderLT[Any] | SupportsDunderGT[Any]")  [return-value]
src\features\temporal.py:578: error: Value of type variable "_NumberT" of "mean" cannot be "Column[Decimal]"  [type-var]
src\features\temporal.py:604: error: Incompatible return value type (got "dict[str, Column[Decimal] | float]", expected "dict[str, float]")  [return-value]
src\features\contextual.py:45: error: Need type annotation for "context_cache" (hint: "context_cache: dict[<type>, <type>] = ...")  [var-annotated]
src\features\contextual.py:138: error: Missing positional argument "room_id" in call to "FeatureExtractionError"  [call-arg]
src\features\contextual.py:147: error: Need type annotation for "env_events"  [var-annotated]
src\features\contextual.py:158: error: Argument 1 to "add" of "set" has incompatible type "Column[Any]"; expected "str"  [arg-type]
src\features\contextual.py:291: error: Argument 1 to "add" of "set" has incompatible type "Column[str]"; expected "str"  [arg-type]
src\features\contextual.py:309: error: Argument "key" to "sort" of "list" has incompatible type "Callable[[SensorEvent], Column[datetime]]"; expected "Callable[[SensorEvent], SupportsDunderLT[Any] | SupportsDunderGT[Any]]"  [arg-type]
src\features\contextual.py:309: error: Incompatible return value type (got "Column[datetime]", expected "SupportsDunderLT[Any] | SupportsDunderGT[Any]")  [return-value]
src\features\contextual.py:338: error: Incompatible types in assignment (expression has type "ColumnElement[float | Decimal] | float", target has type "ColumnElement[bool] | Literal[0]")  [assignment]
src\features\contextual.py:342: error: Incompatible types in assignment (expression has type "int", target has type "ColumnElement[bool] | Literal[0]")  [assignment]
src\features\contextual.py:344: error: Incompatible types in assignment (expression has type "Any | float", target has type "ColumnElement[bool] | Literal[0]")  [assignment]
src\features\contextual.py:350: error: Incompatible types in assignment (expression has type "int", target has type "ColumnElement[bool] | Literal[0]")  [assignment]
src\features\contextual.py:352: error: Incompatible return value type (got "dict[str, ColumnElement[bool] | Literal[0]]", expected "dict[str, float]")  [return-value]
src\features\contextual.py:389: error: Argument "key" to "max" has incompatible type "Callable[[RoomState], Column[datetime]]"; expected "Callable[[RoomState], SupportsDunderLT[Any] | SupportsDunderGT[Any]]"  [arg-type]
src\features\contextual.py:389: error: Incompatible return value type (got "Column[datetime]", expected "SupportsDunderLT[Any] | SupportsDunderGT[Any]")  [return-value]
src\features\contextual.py:395: error: Incompatible types in assignment (expression has type "ColumnElement[float | Decimal] | float", target has type "int")  [assignment]
src\features\contextual.py:400: error: Argument 1 to "_calculate_room_activity_correlation" of "ContextualFeatureExtractor" has incompatible type "defaultdict[Column[str], list[SensorEvent]]"; expected "dict[str, list[SensorEvent]]"  [arg-type]
src\features\contextual.py:402: error: Incompatible types in assignment (expression has type "float", target has type "int")  [assignment]
src\features\contextual.py:412: error: Incompatible types in assignment (expression has type "float", target has type "int")  [assignment]
src\features\contextual.py:415: error: Incompatible types in assignment (expression has type "float", target has type "int")  [assignment]
src\features\contextual.py:428: error: Incompatible types in assignment (expression has type "Any | float", target has type "int")  [assignment]
src\features\contextual.py:431: error: Incompatible types in assignment (expression has type "float", target has type "int")  [assignment]
src\features\contextual.py:433: error: Incompatible return value type (got "dict[str, int]", expected "dict[str, float]")  [return-value]
src\features\contextual.py:433: note: "dict" is invariant -- see https://mypy.readthedocs.io/en/stable/common_issues.html#variance
src\features\contextual.py:433: note: Consider using "Mapping" instead, which is covariant in the value type
src\features\contextual.py:433: note: Perhaps you need a type annotation for "features"? Suggestion: "dict[str, float]"
src\features\contextual.py:483: error: Need type annotation for "window_events"  [var-annotated]
src\features\contextual.py:528: error: Need type annotation for "room_sensor_counts"  [var-annotated]
src\features\contextual.py:535: error: Invalid index type "Column[str]" for "dict[str, set[str]]"; expected type "str"  [index]
src\features\contextual.py:535: error: Argument 1 to "add" of "set" has incompatible type "Column[Any]"; expected "str"  [arg-type]
src\features\contextual.py:539: error: Invalid index type "Column[Any]" for "dict[str, int]"; expected type "str"  [index]
src\features\contextual.py:549: error: Incompatible types in assignment (expression has type "float", target has type "int")  [assignment]
src\features\contextual.py:558: error: Incompatible types in assignment (expression has type "Any | float", target has type "int")  [assignment]
src\features\contextual.py:569: error: Incompatible types in assignment (expression has type "float", target has type "int")  [assignment]
src\features\contextual.py:574: error: Incompatible types in assignment (expression has type "float", target has type "int")  [assignment]
src\features\contextual.py:578: error: Incompatible types in assignment (expression has type "float", target has type "int")  [assignment]
src\features\contextual.py:582: error: Incompatible types in assignment (expression has type "float", target has type "int")  [assignment]
src\features\contextual.py:583: error: Incompatible types in assignment (expression has type "float", target has type "int")  [assignment]
src\features\contextual.py:584: error: Incompatible types in assignment (expression has type "float", target has type "int")  [assignment]
src\features\contextual.py:588: error: Dict entry 0 has incompatible type "str": "float"; expected "str": "int"  [dict-item]
src\features\contextual.py:589: error: Dict entry 1 has incompatible type "str": "float"; expected "str": "int"  [dict-item]
src\features\contextual.py:590: error: Dict entry 2 has incompatible type "str": "float"; expected "str": "int"  [dict-item]
src\features\contextual.py:591: error: Dict entry 3 has incompatible type "str": "float"; expected "str": "int"  [dict-item]
src\features\contextual.py:592: error: Dict entry 4 has incompatible type "str": "float"; expected "str": "int"  [dict-item]
src\features\contextual.py:596: error: Incompatible return value type (got "dict[str, int]", expected "dict[str, float]")  [return-value]
src\features\contextual.py:596: note: "dict" is invariant -- see https://mypy.readthedocs.io/en/stable/common_issues.html#variance
src\features\contextual.py:596: note: Consider using "Mapping" instead, which is covariant in the value type
src\features\contextual.py:596: note: Perhaps you need a type annotation for "features"? Suggestion: "dict[str, float]"
src\data\ingestion\ha_client.py:54: error: Incompatible return value type (got "Literal[''] | bool", expected "bool")  [return-value]
src\data\ingestion\ha_client.py:66: error: Need type annotation for "requests" (hint: "requests: list[<type>] = ...")  [var-annotated]
src\data\ingestion\ha_client.py:371: error: "type[SensorState]" has no attribute "DETECTED"  [attr-defined]
src\data\ingestion\ha_client.py:372: error: "type[SensorState]" has no attribute "CLEAR"  [attr-defined]
src\data\ingestion\ha_client.py:391: error: "type[SensorState]" has no attribute "DETECTED"  [attr-defined]
src\data\ingestion\ha_client.py:393: error: "type[SensorState]" has no attribute "CLEAR"  [attr-defined]
src\data\ingestion\ha_client.py:420: error: "None" has no attribute "__await__"  [attr-defined]
src\data\ingestion\ha_client.py:474: error: Need type annotation for "future"  [var-annotated]
src\data\ingestion\ha_client.py:519: error: Unexpected keyword argument "resource" for "RateLimitExceededError"  [call-arg]
src\core\exceptions.py:659: note: "RateLimitExceededError" defined here
src\data\ingestion\ha_client.py:519: error: Unexpected keyword argument "wait_time" for "RateLimitExceededError"  [call-arg]
src\data\ingestion\ha_client.py:519: error: Unexpected keyword argument "requests_per_window" for "RateLimitExceededError"  [call-arg]
src\data\ingestion\ha_client.py:523: error: Argument "window_seconds" to "RateLimitExceededError" has incompatible type "float"; expected "int"  [arg-type]
src\data\ingestion\ha_client.py:583: error: Unexpected keyword argument "resource" for "RateLimitExceededError"  [call-arg]
src\data\ingestion\ha_client.py:583: error: Unexpected keyword argument "wait_time" for "RateLimitExceededError"  [call-arg]
src\data\ingestion\ha_client.py:583: error: Unexpected keyword argument "requests_per_window" for "RateLimitExceededError"  [call-arg]
src\data\ingestion\ha_client.py:587: error: Argument "window_seconds" to "RateLimitExceededError" has incompatible type "float"; expected "int"  [arg-type]
src\data\ingestion\ha_client.py:656: error: "RateLimitExceededError" has no attribute "wait_time"  [attr-defined]
src\data\ingestion\ha_client.py:658: error: "RateLimitExceededError" has no attribute "wait_time"  [attr-defined]
src\data\ingestion\ha_client.py:759: error: Incompatible return value type (got "WebSocketServerProtocol | bool", expected "bool")  [return-value]
src\adaptation\validator.py:462: error: Invalid index type "ModelType | str" for "dict[str, list[str]]"; expected type "str"  [index]
src\adaptation\validator.py:474: error: Argument 2 to "_invalidate_metrics_cache" of "PredictionValidator" has incompatible type "ModelType | str"; expected "str"  [arg-type]
src\adaptation\validator.py:553: error: Argument 2 to "_invalidate_metrics_cache" of "PredictionValidator" has incompatible type "ModelType | str"; expected "str"  [arg-type]
src\adaptation\validator.py:599: error: Argument 2 to "_get_filtered_records" of "PredictionValidator" has incompatible type "ModelType | str | None"; expected "str | None"  [arg-type]
src\adaptation\validator.py:715: error: Argument 2 to "_invalidate_metrics_cache" of "PredictionValidator" has incompatible type "ModelType | str"; expected "str"  [arg-type]
src\adaptation\validator.py:796: error: Need type annotation for "status_counts"  [var-annotated]
src\adaptation\validator.py:848: error: Invalid index type "ModelType | str" for "dict[str, list[str]]"; expected type "str"  [index]
src\adaptation\validator.py:878: error: "AsyncGenerator[AsyncSession, None]" has no attribute "__aenter__"  [attr-defined]
src\adaptation\validator.py:878: error: "AsyncGenerator[AsyncSession, None]" has no attribute "__aexit__"; maybe "__anext__"?  [attr-defined]
src\adaptation\validator.py:914: error: "AsyncGenerator[AsyncSession, None]" has no attribute "__aenter__"  [attr-defined]
src\adaptation\validator.py:914: error: "AsyncGenerator[AsyncSession, None]" has no attribute "__aexit__"; maybe "__anext__"?  [attr-defined]
src\adaptation\validator.py:1055: error: Dict entry 0 has incompatible type "int": "floating[Any]"; expected "int": "float"  [dict-item]
src\adaptation\validator.py:1056: error: Dict entry 1 has incompatible type "int": "floating[Any]"; expected "int": "float"  [dict-item]
src\adaptation\validator.py:1057: error: Dict entry 2 has incompatible type "int": "floating[Any]"; expected "int": "float"  [dict-item]
src\adaptation\validator.py:1058: error: Dict entry 3 has incompatible type "int": "floating[Any]"; expected "int": "float"  [dict-item]
src\adaptation\validator.py:1067: error: Need type annotation for "level_counts"  [var-annotated]
src\adaptation\validator.py:1175: error: Invalid index type "ModelType | str" for "dict[str, list[str]]"; expected type "str"  [index]
src\adaptation\validator.py:1214: error: Need type annotation for "batch_records" (hint: "batch_records: list[<type>] = ...")  [var-annotated]
src\adaptation\validator.py:1250: error: "AsyncGenerator[AsyncSession, None]" has no attribute "__aenter__"  [attr-defined]
src\adaptation\validator.py:1250: error: "AsyncGenerator[AsyncSession, None]" has no attribute "__aexit__"; maybe "__anext__"?  [attr-defined]
src\adaptation\validator.py:1270: error: Argument 2 to "or_" has incompatible type "ColumnElement[bool] | str"; expected "ColumnElement[bool] | _HasClauseElement[bool] | SQLCoreOperations[bool] | ExpressionElementRole[bool] | TypedColumnsClauseRole[bool] | Callable[[], ColumnElement[bool]] | LambdaElement"  [arg-type]
src\adaptation\validator.py:1379: error: "AsyncGenerator[AsyncSession, None]" has no attribute "__aenter__"  [attr-defined]
src\adaptation\validator.py:1379: error: "AsyncGenerator[AsyncSession, None]" has no attribute "__aexit__"; maybe "__anext__"?  [attr-defined]
src\models\base\xgboost_predictor.py:44: error: "object" has no attribute "copy"  [attr-defined]
src\models\base\xgboost_predictor.py:100: error: Missing positional argument "room_id" in call to "ModelTrainingError"  [call-arg]
src\models\base\xgboost_predictor.py:246: error: Missing positional argument "room_id" in call to "ModelTrainingError"  [call-arg]
src\models\base\xgboost_predictor.py:266: error: Missing positional argument "room_id" in call to "ModelPredictionError"  [call-arg]
src\models\base\xgboost_predictor.py:269: error: Missing positional argument "room_id" in call to "ModelPredictionError"  [call-arg]
src\models\base\xgboost_predictor.py:333: error: Missing positional argument "room_id" in call to "ModelPredictionError"  [call-arg]
src\integration\monitoring_api.py:199: error: "MonitoringIntegration" has no attribute "get_monitoring_manager"; maybe "monitoring_manager"?  [attr-defined]
src\integration\monitoring_api.py:230: error: "MonitoringIntegration" has no attribute "get_monitoring_manager"; maybe "monitoring_manager"?  [attr-defined]
src\data\ingestion\event_processor.py:174: error: No overload variant of "get" of "dict" matches argument type "Column[str]"  [call-overload]
src\data\ingestion\event_processor.py:174: note: Possible overload variants:
src\data\ingestion\event_processor.py:174: note:     def get(self, str, None = ..., /) -> RoomConfig
src\data\ingestion\event_processor.py:174: note:     def get(self, str, RoomConfig, /) -> RoomConfig
src\data\ingestion\event_processor.py:174: note:     def [_T] get(self, str, _T, /) -> RoomConfig | _T
src\data\ingestion\event_processor.py:339: error: Need type annotation for "sensor_counts"  [var-annotated]
src\data\ingestion\event_processor.py:358: error: Value of type variable "SupportsRichComparisonT" of "max" cannot be "Column[datetime]"  [type-var]
src\data\ingestion\event_processor.py:358: error: Value of type variable "SupportsRichComparisonT" of "min" cannot be "Column[datetime]"  [type-var]
src\data\ingestion\event_processor.py:413: error: Need type annotation for "transitions"  [var-annotated]
src\data\ingestion\event_processor.py:583: error: "MovementPatternClassifier" has no attribute "classify_movement_sequence"; maybe "classify_movement"?  [attr-defined]
src\data\ingestion\event_processor.py:654: error: Need type annotation for "sensor_frequencies" (hint: "sensor_frequencies: dict[<type>, <type>] = ...")  [var-annotated]
src\data\ingestion\event_processor.py:708: error: "MovementPatternClassifier" has no attribute "classify_movement_sequence"; maybe "classify_movement"?  [attr-defined]
src\data\ingestion\event_processor.py:709: error: "MovementPatternClassifier" has no attribute "classify_movement_sequence"; maybe "classify_movement"?  [attr-defined]
src\data\ingestion\event_processor.py:941: error: Invalid index type "Column[str]" for "dict[str, deque[Any]]"; expected type "str"  [index]
src\data\ingestion\event_processor.py:952: error: Incompatible types in assignment (expression has type "bool", variable has type "Column[bool]")  [assignment]
src\data\ingestion\event_processor.py:954: error: Incompatible types in assignment (expression has type "float", variable has type "Column[Decimal]")  [assignment]
src\data\ingestion\event_processor.py:959: error: Incompatible types in assignment (expression has type "dict[Never, Never]", variable has type "Column[Any]")  [assignment]
src\data\ingestion\event_processor.py:974: error: Incompatible types in assignment (expression has type "bool", variable has type "Column[bool]")  [assignment]
src\data\ingestion\event_processor.py:976: error: Incompatible types in assignment (expression has type "float", variable has type "Column[Decimal]")  [assignment]
src\data\ingestion\event_processor.py:997: error: Argument "start_time" to "MovementSequence" has incompatible type "Column[datetime]"; expected "datetime"  [arg-type]
src\data\ingestion\event_processor.py:998: error: Argument "end_time" to "MovementSequence" has incompatible type "Column[datetime]"; expected "datetime"  [arg-type]
src\data\ingestion\event_processor.py:1002: error: Set comprehension has incompatible type Set[Column[str]]; expected Set[str]  [misc]
src\data\ingestion\event_processor.py:1003: error: Set comprehension has incompatible type Set[Column[str]]; expected Set[str]  [misc]
src\data\ingestion\event_processor.py:1044: error: Invalid index type "Column[str]" for "dict[str, deque[Any]]"; expected type "str"  [index]
src\data\ingestion\event_processor.py:1087: error: Invalid index type "Column[str]" for "dict[str, deque[Any]]"; expected type "str"  [index]
src\data\ingestion\event_processor.py:1091: error: Incompatible types in assignment (expression has type "Column[datetime]", target has type "datetime")  [assignment]
src\data\ingestion\event_processor.py:1169: error: Need type annotation for "transition_counts"  [var-annotated]
src\data\ingestion\event_processor.py:1227: error: Unexpected keyword argument "context" for "FeatureExtractionError"  [call-arg]
src\core\exceptions.py:463: note: "FeatureExtractionError" defined here
src\data\ingestion\event_processor.py:1227: error: "FeatureExtractionError" gets multiple values for keyword argument "feature_type"  [misc]
src\adaptation\tracker.py:680: error: Unsupported target for indexed assignment ("object")  [index]
src\adaptation\tracker.py:687: error: "object" has no attribute "append"  [attr-defined]
src\adaptation\tracker.py:692: error: Unsupported target for indexed assignment ("object")  [index]
src\adaptation\tracker.py:702: error: Argument 1 to "len" has incompatible type "object"; expected "Sized"  [arg-type]
src\adaptation\tracker.py:703: error: Argument 1 to "len" has incompatible type "object"; expected "Sized"  [arg-type]
src\adaptation\tracker.py:704: error: Argument 1 to "len" has incompatible type "object"; expected "Sized"  [arg-type]
src\adaptation\tracker.py:857: error: Invalid index type "ModelType | str" for "dict[str, RealTimeMetrics]"; expected type "str"  [index]
src\adaptation\tracker.py:1374: error: Argument "severity" to "AccuracyAlert" has incompatible type "object"; expected "AlertSeverity"  [arg-type]
src\adaptation\tracker.py:1375: error: Argument "trigger_condition" to "AccuracyAlert" has incompatible type "object"; expected "str"  [arg-type]
src\adaptation\tracker.py:1376: error: Argument "current_value" to "AccuracyAlert" has incompatible type "object"; expected "float"  [arg-type]
src\adaptation\tracker.py:1377: error: Argument "threshold_value" to "AccuracyAlert" has incompatible type "object"; expected "float"  [arg-type]
src\adaptation\tracker.py:1378: error: Argument "description" to "AccuracyAlert" has incompatible type "object"; expected "str"  [arg-type]
src\adaptation\tracker.py:1406: error: "object" has no attribute "value"  [attr-defined]
src\adaptation\tracker.py:1482: error: Item "dict[str, RealTimeMetrics]" of "RealTimeMetrics | dict[str, RealTimeMetrics]" has no attribute "window_6h_accuracy"  [union-attr]
src\adaptation\tracker.py:1484: error: Item "dict[str, RealTimeMetrics]" of "RealTimeMetrics | dict[str, RealTimeMetrics]" has no attribute "window_6h_mean_error"  [union-attr]
src\adaptation\tracker.py:1486: error: Item "dict[str, RealTimeMetrics]" of "RealTimeMetrics | dict[str, RealTimeMetrics]" has no attribute "trend_slope"  [union-attr]
src\adaptation\tracker.py:1488: error: Item "dict[str, RealTimeMetrics]" of "RealTimeMetrics | dict[str, RealTimeMetrics]" has no attribute "validation_lag_minutes"  [union-attr]
src\adaptation\tracker.py:1519: error: Item "dict[str, RealTimeMetrics]" of "RealTimeMetrics | dict[str, RealTimeMetrics]" has no attribute "accuracy_trend"  [union-attr]
src\adaptation\drift_detector.py:302: error: Need type annotation for "_ph_sum"  [var-annotated]
src\adaptation\drift_detector.py:303: error: Need type annotation for "_ph_min"  [var-annotated]
src\adaptation\drift_detector.py:304: error: Need type annotation for "_ph_error_history"  [var-annotated]
src\adaptation\drift_detector.py:307: error: Need type annotation for "_feature_baselines" (hint: "_feature_baselines: dict[<type>, <type>] = ...")  [var-annotated]
src\adaptation\drift_detector.py:308: error: Need type annotation for "_pattern_baselines" (hint: "_pattern_baselines: dict[<type>, <type>] = ...")  [var-annotated]
src\adaptation\drift_detector.py:377: error: Unexpected keyword argument "error_context" for "OccupancyPredictionError"; did you mean "error_code"?  [call-arg]
src\core\exceptions.py:25: note: "OccupancyPredictionError" defined here
src\adaptation\drift_detector.py:394: error: Unexpected keyword argument "start_time" for "get_accuracy_metrics" of "PredictionValidator"  [call-arg]
src\adaptation\validator.py:568: note: "get_accuracy_metrics" of "PredictionValidator" defined here
src\adaptation\drift_detector.py:394: error: Unexpected keyword argument "end_time" for "get_accuracy_metrics" of "PredictionValidator"  [call-arg]
src\adaptation\drift_detector.py:401: error: Unexpected keyword argument "start_time" for "get_accuracy_metrics" of "PredictionValidator"  [call-arg]
src\adaptation\drift_detector.py:401: error: Unexpected keyword argument "end_time" for "get_accuracy_metrics" of "PredictionValidator"  [call-arg]
src\adaptation\drift_detector.py:409: error: "AccuracyMetrics" has no attribute "mean_absolute_error_minutes"; maybe "mean_error_minutes" or "median_error_minutes"?  [attr-defined]
src\adaptation\drift_detector.py:410: error: "AccuracyMetrics" has no attribute "mean_absolute_error_minutes"; maybe "mean_error_minutes" or "median_error_minutes"?  [attr-defined]
src\adaptation\drift_detector.py:415: error: "AccuracyMetrics" has no attribute "recent_records"  [attr-defined]
src\adaptation\drift_detector.py:418: error: "AccuracyMetrics" has no attribute "recent_records"  [attr-defined]
src\adaptation\drift_detector.py:426: error: "AccuracyMetrics" has no attribute "confidence_vs_accuracy_correlation"; maybe "confidence_accuracy_correlation"?  [attr-defined]
src\adaptation\drift_detector.py:427: error: "AccuracyMetrics" has no attribute "confidence_vs_accuracy_correlation"; maybe "confidence_accuracy_correlation"?  [attr-defined]
src\adaptation\drift_detector.py:686: error: Incompatible return value type (got "floating[Any] | float", expected "float")  [return-value]
src\adaptation\drift_detector.py:923: error: "AsyncGenerator[AsyncSession, None]" has no attribute "__aenter__"  [attr-defined]
src\adaptation\drift_detector.py:923: error: "AsyncGenerator[AsyncSession, None]" has no attribute "__aexit__"; maybe "__anext__"?  [attr-defined]
src\adaptation\drift_detector.py:955: error: Value of type "object" is not indexable  [index]
src\adaptation\drift_detector.py:955: error: Unsupported target for indexed assignment ("object")  [index]
src\adaptation\drift_detector.py:956: error: Value of type "object" is not indexable  [index]
src\adaptation\drift_detector.py:956: error: Unsupported target for indexed assignment ("object")  [index]
src\adaptation\drift_detector.py:1027: error: "AsyncGenerator[AsyncSession, None]" has no attribute "__aenter__"  [attr-defined]
src\adaptation\drift_detector.py:1027: error: "AsyncGenerator[AsyncSession, None]" has no attribute "__aexit__"; maybe "__anext__"?  [attr-defined]
src\adaptation\drift_detector.py:1091: error: Need type annotation for "_feature_baselines" (hint: "_feature_baselines: dict[<type>, <type>] = ...")  [var-annotated]
src\adaptation\drift_detector.py:1094: error: Need type annotation for "_drift_callbacks" (hint: "_drift_callbacks: list[<type>] = ...")  [var-annotated]
src\adaptation\drift_detector.py:1108: error: Incompatible types in assignment (expression has type "Task[None]", variable has type "None")  [assignment]
src\adaptation\drift_detector.py:1108: note: Maybe you forgot to use "await"?
src\adaptation\drift_detector.py:1139: error: Need type annotation for "drift_results" (hint: "drift_results: list[<type>] = ...")  [var-annotated]
src\adaptation\drift_detector.py:1416: error: Argument 2 to "__init__" of "OccupancyPredictionError" has incompatible type "dict[str, Any] | None"; expected "str | None"  [arg-type]
src\adaptation\drift_detector.py:1416: error: Argument 3 to "__init__" of "OccupancyPredictionError" has incompatible type "ErrorSeverity"; expected "dict[str, Any] | None"  [arg-type]
src\models\ensemble.py:52: error: "object" has no attribute "copy"  [attr-defined]
src\models\ensemble.py:120: error: Missing positional argument "room_id" in call to "ModelTrainingError"  [call-arg]
src\models\ensemble.py:230: error: Missing positional argument "room_id" in call to "ModelTrainingError"  [call-arg]
src\models\ensemble.py:250: error: Missing positional argument "room_id" in call to "ModelPredictionError"  [call-arg]
src\models\ensemble.py:253: error: Missing positional argument "room_id" in call to "ModelPredictionError"  [call-arg]
src\models\ensemble.py:274: error: Missing positional argument "room_id" in call to "ModelPredictionError"  [call-arg]
src\models\ensemble.py:295: error: Missing positional argument "room_id" in call to "ModelPredictionError"  [call-arg]
src\models\ensemble.py:319: error: Incompatible types in assignment (expression has type "float", target has type "int")  [assignment]
src\models\ensemble.py:321: error: Incompatible types in assignment (expression has type "float", variable has type "int")  [assignment]
src\models\ensemble.py:326: error: Value expression in dictionary comprehension has incompatible type "float"; expected type "int"  [misc]
src\models\ensemble.py:329: error: Incompatible return value type (got "dict[str, int]", expected "dict[str, float]")  [return-value]
src\models\ensemble.py:329: note: "dict" is invariant -- see https://mypy.readthedocs.io/en/stable/common_issues.html#variance
src\models\ensemble.py:329: note: Consider using "Mapping" instead, which is covariant in the value type
src\models\ensemble.py:329: note: Perhaps you need a type annotation for "combined_importance"? Suggestion: "dict[str, float]"
src\models\ensemble.py:366: error: Missing positional argument "room_id" in call to "ModelTrainingError"  [call-arg]
src\models\ensemble.py:437: error: Dict entry 0 has incompatible type "str": "str"; expected "str": "float"  [dict-item]
src\models\ensemble.py:441: error: Dict entry 4 has incompatible type "str": "list[str]"; expected "str": "float"  [dict-item]
src\models\ensemble.py:443: error: Dict entry 6 has incompatible type "str": "dict[str, float]"; expected "str": "float"  [dict-item]
src\models\ensemble.py:470: error: Missing positional argument "room_id" in call to "ModelTrainingError"  [call-arg]
src\models\ensemble.py:503: error: Incompatible types in assignment (expression has type "XGBoostPredictor", variable has type "LSTMPredictor")  [assignment]
src\models\ensemble.py:505: error: Incompatible types in assignment (expression has type "HMMPredictor", variable has type "LSTMPredictor")  [assignment]
src\models\ensemble.py:507: error: Incompatible types in assignment (expression has type "GaussianProcessPredictor", variable has type "LSTMPredictor")  [assignment]
src\features\sequential.py:56: error: Need type annotation for "sequence_cache" (hint: "sequence_cache: dict[<type>, <type>] = ...")  [var-annotated]
src\features\sequential.py:92: error: Argument "key" to "sorted" has incompatible type "Callable[[SensorEvent], Column[datetime]]"; expected "Callable[[SensorEvent], SupportsDunderLT[Any] | SupportsDunderGT[Any]]"  [arg-type]
src\features\sequential.py:92: error: Incompatible return value type (got "Column[datetime]", expected "SupportsDunderLT[Any] | SupportsDunderGT[Any]")  [return-value]
src\features\sequential.py:123: error: Missing positional argument "room_id" in call to "FeatureExtractionError"  [call-arg]
src\features\sequential.py:310: error: Incompatible types in assignment (expression has type "float", target has type "int")  [assignment]
src\features\sequential.py:321: error: Incompatible types in assignment (expression has type "float", target has type "int")  [assignment]
src\features\sequential.py:330: error: No overload variant of "get" of "dict" matches argument types "str", "int"  [call-overload]
src\features\sequential.py:330: note: Possible overload variants:
src\features\sequential.py:330: note:     def get(self, Column[Any], None = ..., /) -> int
src\features\sequential.py:330: note:     def get(self, Column[Any], int, /) -> int
src\features\sequential.py:330: note:     def [_T] get(self, Column[Any], _T, /) -> int | _T
src\features\sequential.py:332: error: Incompatible types in assignment (expression has type "Any | float", target has type "int")  [assignment]
src\features\sequential.py:336: error: No overload variant of "get" of "dict" matches argument types "str", "int"  [call-overload]
src\features\sequential.py:336: note: Possible overload variants:
src\features\sequential.py:336: note:     def get(self, Column[Any], None = ..., /) -> int
src\features\sequential.py:336: note:     def get(self, Column[Any], int, /) -> int
src\features\sequential.py:336: note:     def [_T] get(self, Column[Any], _T, /) -> int | _T
src\features\sequential.py:338: error: Incompatible types in assignment (expression has type "Any | float", target has type "int")  [assignment]
src\features\sequential.py:341: error: Incompatible return value type (got "dict[str, int]", expected "dict[str, float]")  [return-value]
src\features\sequential.py:341: note: "dict" is invariant -- see https://mypy.readthedocs.io/en/stable/common_issues.html#variance
src\features\sequential.py:341: note: Consider using "Mapping" instead, which is covariant in the value type
src\features\sequential.py:341: note: Perhaps you need a type annotation for "features"? Suggestion: "dict[str, float]"
src\features\sequential.py:371: error: Need type annotation for "window_events"  [var-annotated]
src\features\sequential.py:384: error: Incompatible types in assignment (expression has type "float", target has type "int")  [assignment]
src\features\sequential.py:396: error: Incompatible types in assignment (expression has type "float", target has type "int")  [assignment]
src\features\sequential.py:406: error: Incompatible types in assignment (expression has type "Any | float", target has type "int")  [assignment]
src\features\sequential.py:411: error: Incompatible types in assignment (expression has type "float", target has type "int")  [assignment]
src\features\sequential.py:413: error: Incompatible types in assignment (expression has type "float", target has type "int")  [assignment]
src\features\sequential.py:414: error: Incompatible types in assignment (expression has type "float", target has type "int")  [assignment]
src\features\sequential.py:428: error: Incompatible types in assignment (expression has type "float", target has type "int")  [assignment]
src\features\sequential.py:432: error: Incompatible types in assignment (expression has type "float", target has type "int")  [assignment]
src\features\sequential.py:453: error: Incompatible types in assignment (expression has type "float", target has type "int")  [assignment]
src\features\sequential.py:457: error: Incompatible types in assignment (expression has type "float", target has type "int")  [assignment]
src\features\sequential.py:479: error: Incompatible types in assignment (expression has type "float", target has type "int")  [assignment]
src\features\sequential.py:481: error: Incompatible types in assignment (expression has type "float", target has type "int")  [assignment]
src\features\sequential.py:483: error: Incompatible return value type (got "dict[str, int]", expected "dict[str, float]")  [return-value]
src\features\sequential.py:483: note: "dict" is invariant -- see https://mypy.readthedocs.io/en/stable/common_issues.html#variance
src\features\sequential.py:483: note: Consider using "Mapping" instead, which is covariant in the value type
src\features\sequential.py:483: note: Perhaps you need a type annotation for "features"? Suggestion: "dict[str, float]"
src\features\sequential.py:536: error: No overload variant of "get" of "dict" matches argument type "Column[str]"  [call-overload]
src\features\sequential.py:536: note: Possible overload variants:
src\features\sequential.py:536: note:     def get(self, str, None = ..., /) -> RoomConfig
src\features\sequential.py:536: note:     def get(self, str, RoomConfig, /) -> RoomConfig
src\features\sequential.py:536: note:     def [_T] get(self, str, _T, /) -> RoomConfig | _T
src\features\sequential.py:738: error: Need type annotation for "current_sequence" (hint: "current_sequence: list[<type>] = ...")  [var-annotated]
src\features\sequential.py:782: error: Argument "start_time" to "MovementSequence" has incompatible type "Column[datetime]"; expected "datetime"  [arg-type]
src\features\sequential.py:783: error: Argument "end_time" to "MovementSequence" has incompatible type "Column[datetime]"; expected "datetime"  [arg-type]
src\features\sequential.py:787: error: Set comprehension has incompatible type Set[Column[str]]; expected Set[str]  [misc]
src\features\sequential.py:788: error: Set comprehension has incompatible type Set[Column[str]]; expected Set[str]  [misc]
src\data\ingestion\bulk_importer.py:112: error: Function "builtins.callable" is not valid as a type  [valid-type]
src\data\ingestion\bulk_importer.py:112: note: Perhaps you meant "typing.Callable" instead of "callable"?
src\data\ingestion\bulk_importer.py:589: error: "AsyncGenerator[AsyncSession, None]" has no attribute "__aenter__"  [attr-defined]
src\data\ingestion\bulk_importer.py:589: error: "AsyncGenerator[AsyncSession, None]" has no attribute "__aexit__"; maybe "__anext__"?  [attr-defined]
src\data\ingestion\bulk_importer.py:591: error: Name "session" already defined on line 589  [no-redef]
src\data\ingestion\bulk_importer.py:727: error: "AsyncGenerator[AsyncSession, None]" has no attribute "__aenter__"  [attr-defined]
src\data\ingestion\bulk_importer.py:727: error: "AsyncGenerator[AsyncSession, None]" has no attribute "__aexit__"; maybe "__anext__"?  [attr-defined]
src\data\ingestion\bulk_importer.py:830: error: "object" has no attribute "append"  [attr-defined]
src\data\ingestion\bulk_importer.py:834: error: "object" has no attribute "append"  [attr-defined]
src\data\ingestion\bulk_importer.py:839: error: "object" has no attribute "append"  [attr-defined]
src\data\ingestion\bulk_importer.py:843: error: "object" has no attribute "append"  [attr-defined]
src\data\ingestion\bulk_importer.py:851: error: Unsupported target for indexed assignment ("object")  [index]
src\data\ingestion\bulk_importer.py:854: error: "object" has no attribute "append"  [attr-defined]
src\data\ingestion\bulk_importer.py:858: error: Unsupported target for indexed assignment ("object")  [index]
src\data\ingestion\bulk_importer.py:885: error: "AsyncGenerator[AsyncSession, None]" has no attribute "__aenter__"  [attr-defined]
src\data\ingestion\bulk_importer.py:885: error: "AsyncGenerator[AsyncSession, None]" has no attribute "__aexit__"; maybe "__anext__"?  [attr-defined]
src\data\ingestion\bulk_importer.py:915: error: "object" has no attribute "append"  [attr-defined]
src\data\ingestion\bulk_importer.py:920: error: "object" has no attribute "append"  [attr-defined]
src\data\ingestion\bulk_importer.py:924: error: "object" has no attribute "extend"  [attr-defined]
src\data\ingestion\bulk_importer.py:941: error: "object" has no attribute "append"  [attr-defined]
src\data\ingestion\bulk_importer.py:945: error: "object" has no attribute "append"  [attr-defined]
src\data\ingestion\bulk_importer.py:948: error: "object" has no attribute "append"  [attr-defined]
src\adaptation\retrainer.py:176: error: "TrainingResult" has no attribute "model_path"  [attr-defined]
src\adaptation\retrainer.py:177: error: "TrainingResult" has no attribute "metrics"  [attr-defined]
src\adaptation\retrainer.py:185: error: "PredictionResult" has no attribute "room_id"  [attr-defined]
src\adaptation\retrainer.py:191: error: "PredictionResult" has no attribute "confidence"; maybe "confidence_score"?  [attr-defined]
src\adaptation\retrainer.py:475: error: Unexpected keyword argument "lookback_days" for "RetrainingRequest"  [call-arg]
src\adaptation\retrainer.py:475: error: Unexpected keyword argument "validation_split" for "RetrainingRequest"  [call-arg]
src\adaptation\retrainer.py:475: error: Unexpected keyword argument "feature_refresh" for "RetrainingRequest"  [call-arg]
src\adaptation\retrainer.py:537: error: Unexpected keyword argument "lookback_days" for "RetrainingRequest"  [call-arg]
src\adaptation\retrainer.py:537: error: Unexpected keyword argument "validation_split" for "RetrainingRequest"  [call-arg]
src\adaptation\retrainer.py:537: error: Unexpected keyword argument "feature_refresh" for "RetrainingRequest"  [call-arg]
src\adaptation\retrainer.py:709: error: Need type annotation for "trigger_counts"  [var-annotated]
src\adaptation\retrainer.py:1130: error: Unexpected keyword argument "max_trials" for "OptimizationConfig"  [call-arg]
src\adaptation\retrainer.py:1130: error: Unexpected keyword argument "timeout_seconds" for "OptimizationConfig"  [call-arg]
src\adaptation\retrainer.py:1130: error: Unexpected keyword argument "optimization_metric" for "OptimizationConfig"  [call-arg]
src\adaptation\retrainer.py:1130: error: Unexpected keyword argument "cross_validation_folds" for "OptimizationConfig"  [call-arg]
src\adaptation\retrainer.py:1130: error: Unexpected keyword argument "search_algorithm" for "OptimizationConfig"  [call-arg]
src\adaptation\retrainer.py:1130: error: Unexpected keyword argument "early_stopping_patience" for "OptimizationConfig"  [call-arg]
src\adaptation\retrainer.py:1171: error: Dict entry 0 has incompatible type "str": "dict[str, Any]"; expected "str": "float"  [dict-item]
src\adaptation\retrainer.py:1175: error: "OptimizationResult" has no attribute "trials_completed"  [attr-defined]
src\adaptation\retrainer.py:1189: error: "OptimizationResult" has no attribute "trials_completed"  [attr-defined]
src\adaptation\retrainer.py:1189: error: "OptimizationConfig" has no attribute "max_trials"  [attr-defined]
src\adaptation\retrainer.py:1283: error: Dict entry 0 has incompatible type "str": "str"; expected "str": "float"  [dict-item]
src\adaptation\retrainer.py:1340: error: Incompatible types in assignment (expression has type "dict[str, bool]", variable has type "dict[str, float]")  [assignment]
src\adaptation\retrainer.py:1340: note: "dict" is invariant -- see https://mypy.readthedocs.io/en/stable/common_issues.html#variance
src\adaptation\retrainer.py:1340: note: Consider using "Mapping" instead, which is covariant in the value type
src\adaptation\retrainer.py:1499: error: "ConceptDriftDetector" has no attribute "classify_drift_severity"  [attr-defined]
src\adaptation\retrainer.py:1522: error: "PredictionValidator" has no attribute "validate_model_predictions"; maybe "validate_prediction"?  [attr-defined]
src\adaptation\retrainer.py:1534: error: Unexpected keyword argument "room_id" for "PredictionResult"  [call-arg]
src\adaptation\retrainer.py:1534: error: Unexpected keyword argument "prediction_time" for "PredictionResult"; did you mean "predicted_time", "prediction_interval", or "prediction_metadata"?  [call-arg]
src\adaptation\retrainer.py:1534: error: Unexpected keyword argument "predicted_occupied_time" for "PredictionResult"; did you mean "predicted_time"?  [call-arg]
src\adaptation\retrainer.py:1534: error: Unexpected keyword argument "predicted_vacant_time" for "PredictionResult"; did you mean "predicted_time"?  [call-arg]
src\adaptation\retrainer.py:1534: error: Unexpected keyword argument "confidence" for "PredictionResult"; did you mean "confidence_score"?  [call-arg]
src\features\engineering.py:107: error: Unsupported operand types for + ("object" and "int")  [operator]
src\features\engineering.py:112: error: Missing positional argument "room_id" in call to "FeatureExtractionError"  [call-arg]
src\features\engineering.py:174: error: Unsupported operand types for + ("object" and "int")  [operator]
src\features\engineering.py:176: error: Unsupported operand types for * ("object" and "int")  [operator]
src\features\engineering.py:177: error: Unsupported operand types for - ("object" and "int")  [operator]
src\features\engineering.py:179: error: Unsupported operand types for / ("float" and "object")  [operator]
src\features\engineering.py:187: error: Unsupported operand types for + ("object" and "int")  [operator]
src\features\engineering.py:189: error: Missing positional argument "room_id" in call to "FeatureExtractionError"  [call-arg]
src\features\engineering.py:262: error: Incompatible return value type (got "list[dict[str, float] | BaseException]", expected "list[dict[str, float]]")  [return-value]
src\features\engineering.py:328: error: Item "BaseException" of "dict[str, float] | BaseException" has no attribute "items"  [union-attr]
src\features\engineering.py:331: error: Value of type "object" is not indexable  [index]
src\features\engineering.py:331: error: Unsupported target for indexed assignment ("object")  [index]
src\features\engineering.py:331: error: Argument 1 to "len" has incompatible type "dict[str, float] | BaseException"; expected "Sized"  [arg-type]
src\features\engineering.py:356: error: Value of type "object" is not indexable  [index]
src\features\engineering.py:356: error: Unsupported target for indexed assignment ("object")  [index]
src\features\engineering.py:370: error: Value of type "object" is not indexable  [index]
src\features\engineering.py:370: error: Unsupported target for indexed assignment ("object")  [index]
src\features\engineering.py:388: error: Value of type "object" is not indexable  [index]
src\features\engineering.py:388: error: Unsupported target for indexed assignment ("object")  [index]
src\features\engineering.py:551: error: "object" has no attribute "append"  [attr-defined]
src\features\engineering.py:556: error: "object" has no attribute "append"  [attr-defined]
src\features\engineering.py:567: error: "object" has no attribute "append"  [attr-defined]
src\features\engineering.py:574: error: "object" has no attribute "append"  [attr-defined]
src\integration\dashboard.py:37: error: Cannot assign to a type  [misc]
src\integration\dashboard.py:38: error: Cannot assign to a type  [misc]
src\integration\dashboard.py:39: error: Cannot assign to a type  [misc]
src\integration\dashboard.py:40: error: Cannot assign to a type  [misc]
src\integration\dashboard.py:41: error: Cannot assign to a type  [misc]
src\integration\dashboard.py:42: error: Cannot assign to a type  [misc]
src\integration\dashboard.py:43: error: Cannot assign to a type  [misc]
src\integration\dashboard.py:44: error: Cannot assign to a type  [misc]
src\integration\dashboard.py:45: error: Cannot assign to a type  [misc]
src\integration\dashboard.py:877: error: List item 0 has incompatible type "dict[str, Any] | Any | dict[str, RealTimeMetrics]"; expected "str"  [list-item]
src\integration\dashboard.py:892: error: Item "AccuracyMetrics" of "dict[str, Any] | AccuracyMetrics" has no attribute "get"  [union-attr]
src\integration\dashboard.py:893: error: Item "AccuracyMetrics" of "dict[str, Any] | AccuracyMetrics" has no attribute "get"  [union-attr]
src\integration\dashboard.py:896: error: Item "AccuracyMetrics" of "dict[str, Any] | AccuracyMetrics" has no attribute "get"  [union-attr]
src\integration\dashboard.py:897: error: Item "AccuracyMetrics" of "dict[str, Any] | AccuracyMetrics" has no attribute "get"  [union-attr]
src\integration\dashboard.py:898: error: Item "AccuracyMetrics" of "dict[str, Any] | AccuracyMetrics" has no attribute "get"  [union-attr]
src\integration\dashboard.py:901: error: Item "AccuracyMetrics" of "dict[str, Any] | AccuracyMetrics" has no attribute "get"  [union-attr]
src\integration\dashboard.py:904: error: Item "AccuracyMetrics" of "dict[str, Any] | AccuracyMetrics" has no attribute "get"  [union-attr]
src\integration\dashboard.py:908: error: Item "AccuracyMetrics" of "dict[str, Any] | AccuracyMetrics" has no attribute "get"  [union-attr]
src\integration\dashboard.py:909: error: Item "AccuracyMetrics" of "dict[str, Any] | AccuracyMetrics" has no attribute "get"  [union-attr]
src\integration\dashboard.py:912: error: Item "AccuracyMetrics" of "dict[str, Any] | AccuracyMetrics" has no attribute "get"  [union-attr]
src\integration\dashboard.py:1030: error: Item "list[dict[str, Any]]" of "dict[str, Any] | list[dict[str, Any]]" has no attribute "get"  [union-attr]
src\integration\dashboard.py:1040: error: Item "list[dict[str, Any]]" of "dict[str, Any] | list[dict[str, Any]]" has no attribute "get"  [union-attr]
src\integration\dashboard.py:1045: error: Item "list[dict[str, Any]]" of "dict[str, Any] | list[dict[str, Any]]" has no attribute "get"  [union-attr]
src\integration\dashboard.py:1050: error: Item "list[dict[str, Any]]" of "dict[str, Any] | list[dict[str, Any]]" has no attribute "get"  [union-attr]
src\integration\dashboard.py:1055: error: Item "list[dict[str, Any]]" of "dict[str, Any] | list[dict[str, Any]]" has no attribute "get"  [union-attr]
src\integration\dashboard.py:1060: error: Item "list[dict[str, Any]]" of "dict[str, Any] | list[dict[str, Any]]" has no attribute "get"  [union-attr]
src\integration\dashboard.py:1145: error: Unsupported right operand type for in ("object")  [operator]
src\integration\dashboard.py:1146: error: Unsupported target for indexed assignment ("object")  [index]
src\integration\dashboard.py:1150: error: "object" has no attribute "update"  [attr-defined]
src\integration\dashboard.py:1154: error: "object" has no attribute "update"  [attr-defined]
src\integration\dashboard.py:1159: error: Unsupported target for indexed assignment ("object")  [index]
src\integration\dashboard.py:1162: error: Unsupported target for indexed assignment ("object")  [index]
src\integration\dashboard.py:1169: error: Unsupported target for indexed assignment ("object")  [index]
src\integration\dashboard.py:1225: error: Need type annotation for "alerts_by_room" (hint: "alerts_by_room: dict[<type>, <type>] = ...")  [var-annotated]
src\integration\dashboard.py:1234: error: Item "AccuracyAlert" of "dict[str, Any] | AccuracyAlert" has no attribute "get"  [union-attr]
src\integration\dashboard.py:1243: error: Item "AccuracyAlert" of "dict[str, Any] | AccuracyAlert" has no attribute "get"  [union-attr]
src\integration\dashboard.py:1249: error: Item "AccuracyAlert" of "dict[str, Any] | AccuracyAlert" has no attribute "get"  [union-attr]
src\integration\dashboard.py:1261: error: Incompatible types in assignment (expression has type "list[dict[str, Any] | AccuracyAlert]", target has type "Collection[str]")  [assignment]
src\integration\dashboard.py:1291: error: Unexpected keyword argument "days_back" for "get_accuracy_trends" of "AccuracyTracker"  [call-arg]
src\adaptation\tracker.py:610: note: "get_accuracy_trends" of "AccuracyTracker" defined here
src\integration\dashboard.py:1357: error: Unsupported target for indexed assignment ("object")  [index]
src\integration\dashboard.py:1501: error: Item "str" of "str | None" has no attribute "get"  [union-attr]
src\integration\dashboard.py:1502: error: Item "str" of "str | None" has no attribute "get"  [union-attr]
src\integration\dashboard.py:1590: error: Unexpected keyword argument "error_context" for "__init__" of "OccupancyPredictionError"; did you mean "error_code"?  [call-arg]
src\core\exceptions.py:25: note: "__init__" of "OccupancyPredictionError" defined here
src\integration\api_server.py:536: error: "Request" has no attribute "request_id"  [attr-defined]
src\integration\api_server.py:541: error: "Request" has no attribute "request_id"  [attr-defined]
src\integration\api_server.py:554: error: "Request" has no attribute "request_id"  [attr-defined]
src\integration\api_server.py:567: error: "Request" has no attribute "request_id"  [attr-defined]
src\integration\api_server.py:579: error: "Request" has no attribute "request_id"  [attr-defined]
src\integration\api_server.py:1313: error: Incompatible types in "await" (actual type "dict[str, Any]", expected type "Awaitable[Any]")  [misc]
src\adaptation\tracking_manager.py:52: error: Cannot assign to a type  [misc]
src\adaptation\tracking_manager.py:53: error: Cannot assign to a type  [misc]
src\adaptation\tracking_manager.py:54: error: Cannot assign to a type  [misc]
src\adaptation\tracking_manager.py:448: error: Unexpected keyword argument "predicted_time" for "record_prediction" of "PredictionValidator"  [call-arg]
src\adaptation\validator.py:422: note: "record_prediction" of "PredictionValidator" defined here
src\adaptation\tracking_manager.py:448: error: Unexpected keyword argument "confidence" for "record_prediction" of "PredictionValidator"  [call-arg]
src\adaptation\tracking_manager.py:448: error: Unexpected keyword argument "model_type" for "record_prediction" of "PredictionValidator"  [call-arg]
src\adaptation\tracking_manager.py:448: error: Unexpected keyword argument "transition_type" for "record_prediction" of "PredictionValidator"  [call-arg]
src\adaptation\tracking_manager.py:448: error: Unexpected keyword argument "prediction_metadata" for "record_prediction" of "PredictionValidator"  [call-arg]
src\adaptation\tracking_manager.py:593: error: Unexpected keyword argument "actual_time" for "validate_prediction" of "PredictionValidator"  [call-arg]
src\adaptation\validator.py:484: note: "validate_prediction" of "PredictionValidator" defined here
src\adaptation\tracking_manager.py:644: error: "PredictionValidator" has no attribute "get_total_predictions"  [attr-defined]
src\adaptation\tracking_manager.py:645: error: "PredictionValidator" has no attribute "get_validation_rate"; maybe "get_validation_stats" or "export_validation_data"?  [attr-defined]
src\adaptation\tracking_manager.py:646: error: "PredictionValidator" has no attribute "_pending_predictions"  [attr-defined]
src\adaptation\tracking_manager.py:961: error: "TrackingManager" has no attribute "_validate_room_predictions"  [attr-defined]
src\adaptation\tracking_manager.py:1014: error: "PredictionValidator" has no attribute "cleanup_old_predictions"; maybe "expire_old_predictions" or "cleanup_old_records"?  [attr-defined]
src\adaptation\tracking_manager.py:1121: error: Incompatible types in "await" (actual type "dict[str, Any]", expected type "Awaitable[Any]")  [misc]
src\adaptation\tracking_manager.py:1282: error: Argument "model_type" to "evaluate_retraining_need" of "AdaptiveRetrainer" has incompatible type "str"; expected "ModelType"  [arg-type]
src\adaptation\tracking_manager.py:1326: error: Argument "model_type" to "evaluate_retraining_need" of "AdaptiveRetrainer" has incompatible type "str"; expected "ModelType"  [arg-type]
src\adaptation\tracking_manager.py:1443: error: Argument "model_type" to "request_retraining" of "AdaptiveRetrainer" has incompatible type "ModelType | str"; expected "ModelType"  [arg-type]
src\adaptation\tracking_manager.py:1549: error: Incompatible types in assignment (expression has type "APIServer", variable has type "None")  [assignment]
src\adaptation\tracking_manager.py:1784: error: "AccuracyTracker" has no attribute "get_room_metrics"; maybe "get_real_time_metrics"?  [attr-defined]
src\adaptation\tracking_manager.py:1786: error: "AccuracyTracker" has no attribute "get_overall_metrics"  [attr-defined]
src\adaptation\tracking_manager.py:1855: error: Unexpected keyword argument "reason" for "RetrainingRequest"  [call-arg]
src\adaptation\tracking_manager.py:1855: error: Unexpected keyword argument "force_retrain" for "RetrainingRequest"  [call-arg]
src\adaptation\tracking_manager.py:1857: error: Argument "model_type" to "RetrainingRequest" has incompatible type "str"; expected "ModelType"  [arg-type]
src\adaptation\tracking_manager.py:1858: error: "type[RetrainingTrigger]" has no attribute "MANUAL"  [attr-defined]
src\adaptation\tracking_manager.py:1862: error: Argument "strategy" to "RetrainingRequest" has incompatible type "str"; expected "RetrainingStrategy"  [arg-type]
src\adaptation\tracking_manager.py:1866: error: Missing positional argument "model_type" in call to "request_retraining" of "AdaptiveRetrainer"  [call-arg]
src\adaptation\tracking_manager.py:1866: error: Argument 1 to "request_retraining" of "AdaptiveRetrainer" has incompatible type "RetrainingRequest"; expected "str"  [arg-type]
src\adaptation\tracking_manager.py:1938: error: Incompatible types in "await" (actual type "dict[str, Any]", expected type "Awaitable[Any]")  [misc]
src\adaptation\tracking_manager.py:1964: error: "AdaptiveRetrainer" has no attribute "get_retraining_stats"; maybe "get_retraining_status", "get_retrainer_stats", or "_select_retraining_strategy"?  [attr-defined]
src\adaptation\tracking_manager.py:2013: error: Incompatible types in assignment (expression has type "WebSocketAPIServer", variable has type "None")  [assignment]
src\adaptation\tracking_manager.py:2018: error: "None" has no attribute "initialize"  [attr-defined]
src\adaptation\tracking_manager.py:2019: error: "None" has no attribute "start"  [attr-defined]
src\main_system.py:32: note: By default the bodies of untyped functions are not checked, consider using --check-untyped-defs  [annotation-unchecked]
src\main_system.py:34: note: By default the bodies of untyped functions are not checked, consider using --check-untyped-defs  [annotation-unchecked]
src\main_system.py:126: error: "MQTTIntegrationManager" has no attribute "cleanup"  [attr-defined]
src\features\store.py:373: error: Argument 1 to "append" of "list" has incompatible type "dict[str, float] | BaseException"; expected "dict[str, float]"  [arg-type]
src\features\store.py:591: error: Unsupported target for indexed assignment ("Collection[str]")  [index]
src\features\store.py:595: error: Unsupported target for indexed assignment ("Collection[str]")  [index]
src\features\store.py:605: error: Unsupported target for indexed assignment ("Collection[str]")  [index]
src\features\store.py:607: error: "Collection[str]" has no attribute "append"  [attr-defined]
src\features\store.py:609: error: Unsupported target for indexed assignment ("Collection[str]")  [index]
src\features\store.py:613: error: "Collection[str]" has no attribute "append"  [attr-defined]
src\features\store.py:617: error: Unsupported target for indexed assignment ("Collection[str]")  [index]
src\adaptation\monitoring_enhanced_tracking.py:28: error: Need type annotation for "_original_methods" (hint: "_original_methods: dict[<type>, <type>] = ...")  [var-annotated]
src\adaptation\monitoring_enhanced_tracking.py:57: error: "PredictionResult" has no attribute "prediction_type"; maybe "prediction_interval"?  [attr-defined]
src\models\training_pipeline.py:345: error: "BaseException" object is not iterable  [misc]
src\models\training_pipeline.py:889: error: Unsupported operand types for % ("range" and "int")  [operator]
src\models\training_pipeline.py:1249: error: Incompatible return value type (got "dict[str, OccupancyEnsemble]", expected "dict[str, BasePredictor]")  [return-value]
src\models\training_pipeline.py:1249: note: "dict" is invariant -- see https://mypy.readthedocs.io/en/stable/common_issues.html#variance
src\models\training_pipeline.py:1249: note: Consider using "Mapping" instead, which is covariant in the value type
src\models\training_pipeline.py:1249: note: Perhaps you need a type annotation for "trained_models"? Suggestion: "dict[str, BasePredictor]"
src\models\training_pipeline.py:1296: error: Incompatible types in assignment (expression has type "ndarray[Any, dtype[Any]]", variable has type "list[float]")  [assignment]
src\models\training_pipeline.py:1391: error: Incompatible return value type (got "tuple[str, dict[str, object]]", expected "tuple[str, dict[str, float]]")  [return-value]
src\models\training_pipeline.py:1447: error: "Collection[str]" has no attribute "append"  [attr-defined]
src\models\training_pipeline.py:1456: error: Unsupported target for indexed assignment ("Collection[str]")  [index]
src\models\training_pipeline.py:1744: error: Unsupported target for indexed assignment ("object")  [index]
src\models\training_pipeline.py:1754: error: Value of type "object" is not indexable  [index]
src\integration\realtime_api_endpoints.py:318: error: "TrackingIntegrationManager" has no attribute "get_realtime_publisher"  [attr-defined]
src\integration\realtime_api_endpoints.py:626: note: By default the bodies of untyped functions are not checked, consider using --check-untyped-defs  [annotation-unchecked]
src\integration\realtime_api_endpoints.py:627: note: By default the bodies of untyped functions are not checked, consider using --check-untyped-defs  [annotation-unchecked]
src\models\training_config.py:544: error: Need type annotation for "config_data"  [var-annotated]
src\models\training_config.py:574: error: Unsupported target for indexed assignment ("dict[Any, Any] | str")  [index]
src\models\training_config.py:603: error: Unsupported target for indexed assignment ("Collection[str]")  [index]
Found 619 errors in 43 files (checked 67 source files)
